Workbook

Sheet raw_data
A1: Observation_ID | B1: Country | C1: Continent | D1: Year | E1: Indicator_Code | F1: Indicator_Name | G1: Development_Dimension | H1: SDG_Link | I1: Value | J1: Unit | K1: Country_Year_Key | L1: Source_Note
A2: GM-00001 | B2: Afghanistan | C2: Asia | D2: 1952 | E2: LIFE_EXP | F2: Life expectancy at birth | G2: Health | H2: SDG 3: Good Health and Well-being | I2: 28.801 | J2: Years | K2: Afghanistan|1952 | L2: Gapminder/Plotly country-year extract reshaped to long indicator format for education
A3: GM-00002 | B3: Afghanistan | C3: Asia | D3: 1952 | E3: POP_TOTAL | F3: Population, total | G3: Demographics | H3: SDG 11: Sustainable Cities and Communities | I3: 8425333 | J3: People | K3: Afghanistan|1952 | L3: Gapminder/Plotly country-year extract reshaped to long indicator format for education
A4: GM-00003 | B4: Afghanistan | C4: Asia | D4: 1952 | E4: GDP_PC | F4: GDP per capita | G4: Economy | H4: SDG 8: Decent Work and Economic Growth | I4: 779.44531 | J4: Source-defined international dollars | K4: Afghanistan|1952 | L4: Gapminder/Plotly country-year extract reshaped to long indicator format for education
A5: GM-00004 | B5: Afghanistan | C5: Asia | D5: 1957 | E5: LIFE_EXP | F5: Life expectancy at birth | G5: Health | H5: SDG 3: Good Health and Well-being | I5: 30.332 | J5: Years | K5: Afghanistan|1957 | L5: Gapminder/Plotly country-year extract reshaped to long indicator format for education
A6: GM-00005 | B6: Afghanistan | C6: Asia | D6: 1957 | E6: POP_TOTAL | F6: Population, total | G6: Demographics | H6: SDG 11: Sustainable Cities and Communities | I6: 9240934 | J6: People | K6: Afghanistan|1957 | L6: Gapminder/Plotly country-year extract reshaped to long indicator format for education
A7: GM-00006 | B7: Afghanistan | C7: Asia | D7: 1957 | E7: GDP_PC | F7: GDP per capita | G7: Economy | H7: SDG 8: Decent Work and Economic Growth | I7: 820.85303 | J7: Source-defined international dollars | K7: Afghanistan|1957 | L7: Gapminder/Plotly country-year extract reshaped to long indicator format for education
A8: GM-00007 | B8: Afghanistan | C8: Asia | D8: 1962 | E8: LIFE_EXP | F8: Life expectancy at birth | G8: Health | H8: SDG 3: Good Health and Well-being | I8: 31.997 | J8: Years | K8: Afghanistan|1962 | L8: Gapminder/Plotly country-year extract reshaped to long indicator format for education
A9: GM-00008 | B9: Afghanistan | C9: Asia | D9: 1962 | E9: POP_TOTAL | F9: Population, total | G9: Demographics | H9: SDG 11: Sustainable Cities and Communities | I9: 10267083 | J9: People | K9: Afghanistan|1962 | L9: Gapminder/Plotly country-year extract reshaped to long indicator format for education
A10: GM-00009 | B10: Afghanistan | C10: Asia | D10: 1962 | E10: GDP_PC | F10: GDP per capita | G10: Economy | H10: SDG 8: Decent Work and Economic Growth | I10: 853.10071 | J10: Source-defined international dollars | K10: Afghanistan|1962 | L10: Gapminder/Plotly country-year extract reshaped to long indicator format for education
A11: GM-00010 | B11: Afghanistan | C11: Asia | D11: 1967 | E11: LIFE_EXP | F11: Life expectancy at birth | G11: Health | H11: SDG 3: Good Health and Well-being | I11: 34.02 | J11: Years | K11: Afghanistan|1967 | L11: Gapminder/Plotly country-year extract reshaped to long indicator format for education
A12: GM-00011 | B12: Afghanistan | C12: Asia | D12: 1967 | E12: POP_TOTAL | F12: Population, total | G12: Demographics | H12: SDG 11: Sustainable Cities and Communities | I12: 11537966 | J12: People | K12: Afghanistan|1967 | L12: Gapminder/Plotly country-year extract reshaped to long indicator format for education
A13: GM-00012 | B13: Afghanistan | C13: Asia | D13: 1967 | E13: GDP_PC | F13: GDP per capita | G13: Economy | H13: SDG 8: Decent Work and Economic Growth | I13: 836.19714 | J13: Source-defined international dollars | K13: Afghanistan|1967 | L13: Gapminder/Plotly country-year extract reshaped to long indicator format for education
... A5113: GM-05112 | B5113: Zimbabwe | C5113: Africa | D5113: 2007 | E5113: GDP_PC | F5113: GDP per capita | G5113: Economy | H5113: SDG 8: Decent Work and Economic Growth | I5113: 469.7093 | J5113: Source-defined international dollars | K5113: Zimbabwe|2007 | L5113: Gapminder/Plotly country-year extract reshaped to long indicator format for education

Sheet cleaned_data
A1: Observation_ID | B1: Country | C1: Continent | D1: Year | E1: Indicator_Code | F1: Indicator_Name | G1: Development_Dimension | H1: SDG_Link | I1: Value | J1: Unit | K1: Country_Year_Key | L1: Source_Note | M1: Value_Check | N1: Decade | O1: Value_Band | P1: Dimension_Lookup
A2: GM-00001 | B2: Afghanistan | C2: Asia | D2: 1952 | E2: LIFE_EXP | F2: Life expectancy at birth | G2: Health | H2: SDG 3: Good Health and Well-being | I2: 28.801 | J2: Years | K2: Afghanistan|1952 | L2: Gapminder/Plotly country-year extract reshaped to long indicator format for education | M2: =IF(AND(ISNUMBER(I2),I2>=0),"OK","Review") -> OK | N2: =FLOOR(D2,10)&"s" -> 1950s | O2: =IF(E2="LIFE_EXP",IF(I2>=70,"High",IF(I2>=55,"Medium","Low")),"N/A") -> Low | P2: =VLOOKUP(E2,calculated_fields!$F$4:$G$6,2,FALSE) -> Health
A3: GM-00002 | B3: Afghanistan | C3: Asia | D3: 1952 | E3: POP_TOTAL | F3: Population, total | G3: Demographics | H3: SDG 11: Sustainable Cities and Communities | I3: 8425333 | J3: People | K3: Afghanistan|1952 | L3: Gapminder/Plotly country-year extract reshaped to long indicator format for education | M3: =IF(AND(ISNUMBER(I3),I3>=0),"OK","Review") -> OK | N3: =FLOOR(D3,10)&"s" -> 1950s | O3: =IF(E3="LIFE_EXP",IF(I3>=70,"High",IF(I3>=55,"Medium","Low")),"N/A") -> N/A | P3: =VLOOKUP(E3,calculated_fields!$F$4:$G$6,2,FALSE) -> Demographics
A4: GM-00003 | B4: Afghanistan | C4: Asia | D4: 1952 | E4: GDP_PC | F4: GDP per capita | G4: Economy | H4: SDG 8: Decent Work and Economic Growth | I4: 779.44531 | J4: Source-defined international dollars | K4: Afghanistan|1952 | L4: Gapminder/Plotly country-year extract reshaped to long indicator format for education | M4: =IF(AND(ISNUMBER(I4),I4>=0),"OK","Review") -> OK | N4: =FLOOR(D4,10)&"s" -> 1950s | O4: =IF(E4="LIFE_EXP",IF(I4>=70,"High",IF(I4>=55,"Medium","Low")),"N/A") -> N/A | P4: =VLOOKUP(E4,calculated_fields!$F$4:$G$6,2,FALSE) -> Economy
A5: GM-00004 | B5: Afghanistan | C5: Asia | D5: 1957 | E5: LIFE_EXP | F5: Life expectancy at birth | G5: Health | H5: SDG 3: Good Health and Well-being | I5: 30.332 | J5: Years | K5: Afghanistan|1957 | L5: Gapminder/Plotly country-year extract reshaped to long indicator format for education | M5: =IF(AND(ISNUMBER(I5),I5>=0),"OK","Review") -> OK | N5: =FLOOR(D5,10)&"s" -> 1950s | O5: =IF(E5="LIFE_EXP",IF(I5>=70,"High",IF(I5>=55,"Medium","Low")),"N/A") -> Low | P5: =VLOOKUP(E5,calculated_fields!$F$4:$G$6,2,FALSE) -> Health
A6: GM-00005 | B6: Afghanistan | C6: Asia | D6: 1957 | E6: POP_TOTAL | F6: Population, total | G6: Demographics | H6: SDG 11: Sustainable Cities and Communities | I6: 9240934 | J6: People | K6: Afghanistan|1957 | L6: Gapminder/Plotly country-year extract reshaped to long indicator format for education | M6: =IF(AND(ISNUMBER(I6),I6>=0),"OK","Review") -> OK | N6: =FLOOR(D6,10)&"s" -> 1950s | O6: =IF(E6="LIFE_EXP",IF(I6>=70,"High",IF(I6>=55,"Medium","Low")),"N/A") -> N/A | P6: =VLOOKUP(E6,calculated_fields!$F$4:$G$6,2,FALSE) -> Demographics
A7: GM-00006 | B7: Afghanistan | C7: Asia | D7: 1957 | E7: GDP_PC | F7: GDP per capita | G7: Economy | H7: SDG 8: Decent Work and Economic Growth | I7: 820.85303 | J7: Source-defined international dollars | K7: Afghanistan|1957 | L7: Gapminder/Plotly country-year extract reshaped to long indicator format for education | M7: =IF(AND(ISNUMBER(I7),I7>=0),"OK","Review") -> OK | N7: =FLOOR(D7,10)&"s" -> 1950s | O7: =IF(E7="LIFE_EXP",IF(I7>=70,"High",IF(I7>=55,"Medium","Low")),"N/A") -> N/A | P7: =VLOOKUP(E7,calculated_fields!$F$4:$G$6,2,FALSE) -> Economy
A8: GM-00007 | B8: Afghanistan | C8: Asia | D8: 1962 | E8: LIFE_EXP | F8: Life expectancy at birth | G8: Health | H8: SDG 3: Good Health and Well-being | I8: 31.997 | J8: Years | K8: Afghanistan|1962 | L8: Gapminder/Plotly country-year extract reshaped to long indicator format for education | M8: =IF(AND(ISNUMBER(I8),I8>=0),"OK","Review") -> OK | N8: =FLOOR(D8,10)&"s" -> 1960s | O8: =IF(E8="LIFE_EXP",IF(I8>=70,"High",IF(I8>=55,"Medium","Low")),"N/A") -> Low | P8: =VLOOKUP(E8,calculated_fields!$F$4:$G$6,2,FALSE) -> Health
A9: GM-00008 | B9: Afghanistan | C9: Asia | D9: 1962 | E9: POP_TOTAL | F9: Population, total | G9: Demographics | H9: SDG 11: Sustainable Cities and Communities | I9: 10267083 | J9: People | K9: Afghanistan|1962 | L9: Gapminder/Plotly country-year extract reshaped to long indicator format for education | M9: =IF(AND(ISNUMBER(I9),I9>=0),"OK","Review") -> OK | N9: =FLOOR(D9,10)&"s" -> 1960s | O9: =IF(E9="LIFE_EXP",IF(I9>=70,"High",IF(I9>=55,"Medium","Low")),"N/A") -> N/A | P9: =VLOOKUP(E9,calculated_fields!$F$4:$G$6,2,FALSE) -> Demographics
A10: GM-00009 | B10: Afghanistan | C10: Asia | D10: 1962 | E10: GDP_PC | F10: GDP per capita | G10: Economy | H10: SDG 8: Decent Work and Economic Growth | I10: 853.10071 | J10: Source-defined international dollars | K10: Afghanistan|1962 | L10: Gapminder/Plotly country-year extract reshaped to long indicator format for education | M10: =IF(AND(ISNUMBER(I10),I10>=0),"OK","Review") -> OK | N10: =FLOOR(D10,10)&"s" -> 1960s | O10: =IF(E10="LIFE_EXP",IF(I10>=70,"High",IF(I10>=55,"Medium","Low")),"N/A") -> N/A | P10: =VLOOKUP(E10,calculated_fields!$F$4:$G$6,2,FALSE) -> Economy
A11: GM-00010 | B11: Afghanistan | C11: Asia | D11: 1967 | E11: LIFE_EXP | F11: Life expectancy at birth | G11: Health | H11: SDG 3: Good Health and Well-being | I11: 34.02 | J11: Years | K11: Afghanistan|1967 | L11: Gapminder/Plotly country-year extract reshaped to long indicator format for education | M11: =IF(AND(ISNUMBER(I11),I11>=0),"OK","Review") -> OK | N11: =FLOOR(D11,10)&"s" -> 1960s | O11: =IF(E11="LIFE_EXP",IF(I11>=70,"High",IF(I11>=55,"Medium","Low")),"N/A") -> Low | P11: =VLOOKUP(E11,calculated_fields!$F$4:$G$6,2,FALSE) -> Health
A12: GM-00011 | B12: Afghanistan | C12: Asia | D12: 1967 | E12: POP_TOTAL | F12: Population, total | G12: Demographics | H12: SDG 11: Sustainable Cities and Communities | I12: 11537966 | J12: People | K12: Afghanistan|1967 | L12: Gapminder/Plotly country-year extract reshaped to long indicator format for education | M12: =IF(AND(ISNUMBER(I12),I12>=0),"OK","Review") -> OK | N12: =FLOOR(D12,10)&"s" -> 1960s | O12: =IF(E12="LIFE_EXP",IF(I12>=70,"High",IF(I12>=55,"Medium","Low")),"N/A") -> N/A | P12: =VLOOKUP(E12,calculated_fields!$F$4:$G$6,2,FALSE) -> Demographics
A13: GM-00012 | B13: Afghanistan | C13: Asia | D13: 1967 | E13: GDP_PC | F13: GDP per capita | G13: Economy | H13: SDG 8: Decent Work and Economic Growth | I13: 836.19714 | J13: Source-defined international dollars | K13: Afghanistan|1967 | L13: Gapminder/Plotly country-year extract reshaped to long indicator format for education | M13: =IF(AND(ISNUMBER(I13),I13>=0),"OK","Review") -> OK | N13: =FLOOR(D13,10)&"s" -> 1960s | O13: =IF(E13="LIFE_EXP",IF(I13>=70,"High",IF(I13>=55,"Medium","Low")),"N/A") -> N/A | P13: =VLOOKUP(E13,calculated_fields!$F$4:$G$6,2,FALSE) -> Economy
... A5113: GM-05112 | B5113: Zimbabwe | C5113: Africa | D5113: 2007 | E5113: GDP_PC | F5113: GDP per capita | G5113: Economy | H5113: SDG 8: Decent Work and Economic Growth | I5113: 469.7093 | J5113: Source-defined international dollars | K5113: Zimbabwe|2007 | L5113: Gapminder/Plotly country-year extract reshaped to long indicator format for education | M5113: =IF(AND(ISNUMBER(I5113),I5113>=0),"OK","Review") -> OK | N5113: =FLOOR(D5113,10)&"s" -> 2000s | O5113: =IF(E5113="LIFE_EXP",IF(I5113>=70,"High",IF(I5113>=55,"Medium","Low")),"N/A") -> N/A | P5113: =VLOOKUP(E5113,calculated_fields!$F$4:$G$6,2,FALSE) -> Economy

Sheet quality_checks
A1: Data Quality Checks
A3: Checks | B3: Formula / Method | C3: Result | D3: Interpretation
A4: Total observations | B4: COUNTA on Observation_ID | C4: =COUNTA(cleaned_data!A:A)-1 -> 5112 | D4: 5,112 observations available for analysis.
A5: Blank Observation IDs | B5: COUNTBLANK on Observation_ID | C5: =COUNTBLANK(cleaned_data!A2:A5113) -> 0 | D5: No missing observation IDs identified.
A6: LIFE_EXP rows | B6: COUNTIF on Indicator_Code | C6: =COUNTIF(cleaned_data!E:E,"LIFE_EXP") -> 1704 | D6: Balanced indicator coverage.
A7: POP_TOTAL rows | B7: COUNTIF on Indicator_Code | C7: =COUNTIF(cleaned_data!E:E,"POP_TOTAL") -> 1704 | D7: Balanced indicator coverage.
A8: GDP_PC rows | B8: COUNTIF on Indicator_Code | C8: =COUNTIF(cleaned_data!E:E,"GDP_PC") -> 1704 | D8: Balanced indicator coverage.
A9: Minimum year | B9: MIN on Year | C9: =MIN(cleaned_data!D2:D5113) -> 1952 | D9: Earliest observation year.
A10: Maximum year | B10: MAX on Year | C10: =MAX(cleaned_data!D2:D5113) -> 2007 | D10: Latest observation year.
A11: Minimum value | B11: MIN on Value | C11: =MIN(cleaned_data!I2:I5113) -> 23.599 | D11: No negative values identified
A12: Maximum value | B12: MAX on Value | C12: =MAX(cleaned_data!I2:I5113) -> 1318683096 | D12: Maximum value in the dataset
A13: Rows needing review | B13: COUNTIF on Value_Check | C13: =COUNTIF(cleaned_data!M:M,"Review") -> 0 | D13: No negative or non-numeric values identified.

Sheet calculated_fields
A2: Calculated Fields and Formula Analysis
A3: Field / Analysis | B3: Formula / Method | C3: Result / Purpose | D3: Comment | F3: Indicator_Code | G3: Development_Dimension
A4: Value_Check | B4: IF + AND + ISNUMBER | C4: Flags invalid or negative values | F4: LIFE_EXP | G4: Health
A5: Decade | B5: FLOOR | C5: Groups observation years into decades | F5: POP_TOTAL | G5: Demographics
A6: Value_Band | B6: Nested IF | C6: Categorises life expectancy into Low/Medium/High | F6: GDP_PC | G6: Economy
A7: Africa row count | B7: COUNTIF on Continent | C7: =COUNTIF(cleaned_data!C:C,"Africa") -> 1872 | D7: Counts observations recorded for Africa.
A8: Asia population total (2007) | B8: SUMIFS | C8: 3811953827
A9: Dimension_Lookup | B9: VLOOKUP | C9: Maps indicator codes to development dimensions
A10: Average life expectancy | B10: AVERAGEIF | C10: =AVERAGEIF(cleaned_data!E:E,"LIFE_EXP",cleaned_data!I:I) -> 59.474439 | D10: Average life expectancy across all country-year observations.
A13: Key Analytical Metrics
A14: Metric | B14: Result | C14: Interpretation
A15: Africa life expectancy increase (1952–2007) | B15: =pivot_analysis!B16-pivot_analysis!B5 -> 15.670538 | C15: Life expectancy in Africa increased by approximately 15.67 years between 1952 and 2007.
A16: Asia life expectancy increase (1952–2007) | B16: =pivot_analysis!D16-pivot_analysis!D5 -> 24.414091 | C16: Life expectancy in Asia increased by approximately 24.41 years between 1952 and 2007.
A17: Highest 2007 life expectancy continent | B17: =INDEX(pivot_analysis!B4:F4,1,MATCH(MAX(pivot_analysis!B16:F16),pivot_analysis!B16:F16,0))&" — "&TEXT(MAX(pivot_analysis!B16:F16),"0.00")&" years" -> Oceania — 80.72 years | C17: Oceania had the highest average life expectancy in 2007 at approximately 80.72 years.
A18: Highest 2007 GDP per capita continent | B18: =INDEX(pivot_analysis!B35:F35,1,MATCH(MAX(pivot_analysis!B47:F47),pivot_analysis!B47:F47,0))&" — "&TEXT(MAX(pivot_analysis!B47:F47),"#,##0.00") -> Oceania — 29,810.19 | C18: Oceania had the highest average GDP per capita in 2007 at approximately 29,810.19.
A19: Largest 2007 population continent | B19: =INDEX(pivot_analysis!A23:A27,MATCH(MAX(pivot_analysis!B23:B27),pivot_analysis!B23:B27,0))&" — "&TEXT(MAX(pivot_analysis!B23:B27),"#,##0") -> Asia — 3,811,953,827 | C19: Asia had the largest population in 2007, with approximately 3.81 billion people represented in the dataset.

Sheet pivot_analysis
A1: Indicator_Code | B1: LIFE_EXP
A3: Average of Value | B3: Continent
A4: Year | B4: Africa | C4: Americas | D4: Asia | E4: Europe | F4: Oceania | G4: Grand Total
A5: 1952 | B5: 39.1355 | C5: 53.27984 | D5: 46.314394 | E5: 64.4085 | F5: 69.255 | G5: 49.05762
A6: 1957 | B6: 41.266346 | C6: 55.96028 | D6: 49.318544 | E6: 66.703067 | F6: 70.295 | G6: 51.507401
A7: 1962 | B7: 43.319442 | C7: 58.39876 | D7: 51.563223 | E7: 68.539233 | F7: 71.085 | G7: 53.609249
A8: 1967 | B8: 45.334538 | C8: 60.41092 | D8: 54.66364 | E8: 69.7376 | F8: 71.31 | G8: 55.67829
A9: 1972 | B9: 47.450942 | C9: 62.39492 | D9: 57.319269 | E9: 70.775033 | F9: 71.91 | G9: 57.647386
A10: 1977 | B10: 49.580423 | C10: 64.39156 | D10: 59.610556 | E10: 71.937767 | F10: 72.855 | G10: 59.570157
A11: 1982 | B11: 51.592865 | C11: 66.22884 | D11: 62.617939 | E11: 72.8064 | F11: 74.29 | G11: 61.533197
A12: 1987 | B12: 53.344788 | C12: 68.09072 | D12: 64.851182 | E12: 73.642167 | F12: 75.32 | G12: 63.212613
A13: 1992 | B13: 53.629577 | C13: 69.56836 | D13: 66.537212 | E13: 74.4401 | F13: 76.945 | G13: 64.160338
A14: 1997 | B14: 53.598269 | C14: 71.15048 | D14: 68.020515 | E14: 75.505167 | F14: 78.19 | G14: 65.014676
A15: 2002 | B15: 53.325231 | C15: 72.42204 | D15: 69.233879 | E15: 76.7006 | F15: 79.74 | G15: 65.694923
A16: 2007 | B16: 54.806038 | C16: 73.60812 | D16: 70.728485 | E16: 77.6486 | F16: 80.7195 | G16: 67.007423
A17: Grand Total | B17: 48.86533 | C17: 64.658737 | D17: 60.064903 | E17: 71.903686 | F17: 74.326208 | G17: 59.474439
A19: Indicator_Code | B19: POP_TOTAL
A20: Year | B20: 2007
A22: Continent | B22: Sum of Value
A23: Africa | B23: 929539692
A24: Americas | B24: 898871184
A25: Asia | B25: 3811953827
A26: Europe | B26: 586098529
A27: Oceania | B27: 24549947
A28: Grand Total | B28: 6251013179
A32: Indicator_Code | B32: GDP_PC
A34: Average of Value | B34: Continent
A35: Year | B35: Africa | C35: Americas | D35: Asia | E35: Europe | F35: Oceania | G35: Grand Total
A36: 1952 | B36: 1252.5725 | C36: 4079.0626 | D36: 5195.484 | E36: 5661.0574 | F36: 10298.086 | G36: 3725.276
A37: 1957 | B37: 1385.2361 | C37: 4616.0437 | D37: 5787.7329 | E37: 6963.0128 | F37: 11598.522 | G37: 4299.4083
A38: 1962 | B38: 1598.0788 | C38: 4901.5419 | D38: 5729.3696 | E38: 8365.4868 | F38: 12696.452 | G38: 4725.8123
A39: 1967 | B39: 2050.3638 | C39: 5668.2535 | D39: 5971.1734 | E39: 10143.824 | F39: 14495.022 | G39: 5483.653
A40: 1972 | B40: 2339.6157 | C40: 6491.3341 | D40: 8187.4687 | E40: 12479.575 | F40: 16417.333 | G40: 6770.0828
A41: 1977 | B41: 2585.9385 | C41: 7352.0071 | D41: 7791.314 | E41: 14283.979 | F41: 17283.958 | G41: 7313.1664
A42: 1982 | B42: 2481.593 | C42: 7506.7371 | D42: 7434.1352 | E42: 15617.897 | F42: 18554.71 | G42: 7518.9017
A43: 1987 | B43: 2282.669 | C43: 7793.4003 | D43: 7608.2265 | E43: 17214.311 | F43: 20448.04 | G43: 7900.9202
A44: 1992 | B44: 2281.8103 | C44: 8044.9344 | D44: 8639.6902 | E44: 17061.568 | F44: 20894.046 | G44: 8158.6085
A45: 1997 | B45: 2378.7596 | C45: 8889.3009 | D45: 9834.0933 | E45: 19076.782 | F45: 24024.175 | G45: 9090.1754
A46: 2002 | B46: 2599.3852 | C46: 9287.6771 | D46: 10174.09 | E46: 21711.732 | F46: 26938.778 | G46: 9917.8484
A47: 2007 | B47: 3089.0326 | C47: 11003.032 | D47: 12473.027 | E47: 25054.482 | F47: 29810.188 | G47: 11680.072
...

Sheet charts

Sheet dashboard
C2: GLOBAL DEVELOPMENT DASHBOARD
B7: Overall Avg Life Expectancy | G7: Africa Life Expentency Change | K7: Asia Life Expentency Change | P7: Largest 2007 Population
B11: 59.47 years | G11: +15.67 years | K11: +24.41 years | P11: Asia · 3.81B
L35: KEY INSIGHTS
L37: Life expectancy improved globally Average life expectancy was 59.47 years, with long-term improvements across all continents. | Q37: Asia recorded strong improvement Average life expectancy increased by 24.41 years between 1952 and 2007.
L45: Oceania leads on 2007 outcomes It recorded the highest average life expectancy (80.72 years) and GDP per capita (29,810.19) in 2007. | Q45: Asia dominates population size Asia represented approximately 3.81 billion people in 2007, far exceeding every other continent.
C55: Analysis: Life Expectancy, Population and GDP per Capita | 1952–2007

Sheet Insights_Report
A1: UN Development Indicators — Analytical Insights Report
A3: Analysis Overview
A4: This analysis examines long-term patterns in life expectancy, population and GDP per capita across five continents between 1952 and 2007. The analysis uses cleaned indicator data, calculated fields and PivotTables to compare health, demographic and economic development.
A7: Key Findings
A8: Life Expectancy Improvement
A9: Average life expectancy increased across all five continents between 1952 and 2007. Asia recorded an increase of approximately 24.41 years, compared with approximately 15.67 years in Africa.
A11: Life Expectancy in 2007
A12: Oceania recorded the highest average life expectancy in 2007 at approximately 80.72 years, followed by Europe at approximately 77.65 years.
A14: Population Distribution
A15: Asia had the largest population represented in the dataset in 2007 at approximately 3.81 billion people, substantially exceeding the other continental groups.
A17: Economic Development
A18: Average GDP per capita increased substantially over the study period. In 2007, Oceania recorded the highest continental average at approximately 29,810.19, followed by Europe at approximately 25,054.48.
... A21: The results indicate broad improvements in health and economic indicators over time, although substantial differences remained between continents. The analysis also highlights that population size, economic output per person and health outcomes represent different dimensions of development and should be interpreted together rather than in isolation.
